Workbook
Name \a: #REF!
Name \i: #REF!
Name \j: #REF!
Name \k: #REF!
Name \p: #REF!
Name ________abr01: #REF!
Name ________PIB04: #REF!
Name ________PIB05: #REF!
Name ________PIB06: #REF!
Name ________PIB90: #REF!
Name ________PIB91: #REF!
Name ________PIB92: #REF!
Name ________PIB93: #REF!
Name ________PIB94: #REF!
Name ________PIB95: #REF!
Name ________PIB96: #REF!
Name ________PIB97: #REF!
Name ________PIB98: #REF!
Name ________PIB99: #REF!
Name _______PIB01: #REF!
Name _______PIB02: #REF!
Name _______PIB03: #REF!
Name ______abr01: #REF!
Name ______PIB01: #REF!
Name ______PIB02: #REF!
Name ______PIB03: #REF!
Name ______PIB04: #REF!
Name ______PIB05: #REF!
Name ______PIB06: #REF!
Name ______PIB90: #REF!
Name ______PIB91: #REF!
Name ______PIB92: #REF!
Name ______PIB93: #REF!
Name ______PIB94: #REF!
Name ______PIB95: #REF!
Name ______PIB96: #REF!
Name ______PIB97: #REF!
Name ______PIB98: #REF!
Name ______PIB99: #REF!
Name _____abr01: #REF!
Name _____PIB01: #REF!
Name _____PIB02: #REF!
Name _____PIB03: #REF!
Name _____PIB04: #REF!
Name _____PIB05: #REF!
Name _____PIB06: #REF!
Name _____PIB90: #REF!
Name _____PIB91: #REF!
Name _____PIB92: #REF!
Name _____PIB93: #REF!
Name _____PIB94: #REF!
Name _____PIB95: #REF!
Name _____PIB96: #REF!
Name _____PIB97: #REF!
Name _____PIB98: #REF!
Name _____PIB99: #REF!
Name ____abr01: #REF!
Name ____PIB01: #REF!
Name ____PIB02: #REF!
Name ____PIB03: #REF!

Sheet Datos_Trimestrales
A2: Plantilla de datos para estimación de modelo FISLAC - Brasil
A4: Nota: por favor completar la información con la mayor cantidad de datos históricos disponibles
C7: Sector Real | P7: Sector Monetario | V7: Balanza de Pagos | AJ7: Sector Fiscal
B8: Años | C8: PIB Nominal | D8: PIB Real | E8: PIB potencial | F8: Brecha del PIB | G8: Crecimiento PIB Real | H8: Inversión Privada | I8: Inversión Privada % del PIB | J8: Consumo Privado | K8: Consumo Privado % del PIB | L8: Importaciones | M8: Importaciones % del PIB | N8: Exportaciones | O8: Exportaciones % del PIB | P8: Inflación (%) | Q8: Tasa de Política Monetaria (%) | R8: Tasa activa promedio (%) | S8: Tasa pasiva promedio (%) | T8: Tasa de Cambio (por Dólar) | U8: PIB nominal (USD) | V8: Saldo Cuenta Corriente (USD) | W8: Saldo Cuenta Corriente % del PIB | X8: Saldo Cuenta Capital (USD) | Y8: Saldo Cuenta Capital % del PIB | Z8: Saldo Cuenta financiera (USD) | AA8: Saldo Cuenta financiera % del PIB | AB8: Errores y omisiones (USD) | AC8: Errores y omisiones % del PIB | AD8: Reservas Internacionales Netas (USD) | AE8: Reservas Internacionales Netas % del PIB | AF8: Remesas Internacionales (USD) | AG8: Remesas Internacionales % del PIB | AH8: Inversión extranjera directa (USD) | AI8: Inversión extranjera directa % del PIB | AJ8: Ingreso Fiscal (Total) | AK8: Ingreso Fiscal (Total) % del PIB | AL8: Ingreso por Materias Primas | AM8: Ingreso por Materias Primas % del PIB | AN8: Ingreso Tributario | AO8: Ingreso Tributario % del PIB | AP8: Ingreso Impuestos Consumo | AQ8: Ingreso Impuestos Consumo % del PIB | AR8: Ingreso Impuestos Renta Laboral | AS8: Ingreso Impuestos Renta Laboral % del PIB | AT8: Ingreso Impuestos Renta de capital | AU8: Ingreso Impuestos Renta de capital % del PIB | AV8: Ingreso Impuestos Renta de Empresas | AW8: Ingreso Impuestos Renta de Empresas % del PIB | AX8: Ingreso Otros | AY8: Ingreso Otros % del PIB | AZ8: Gasto Público Total | BA8: Gasto Público Total % del PIB | BB8: Gasto Público Primario | BC8: Gasto Público Primario % del PIB | BD8: Gasto Corriente Primario | BE8: Gasto Corriente Primario % del PIB | BF8: Gasto en atención a desastres naturales | BG8: Gasto en atención a desastres naturales % del PIB | BH8: Gasto de Capital | BI8: Gasto de Capital % del PIB | BJ8: Inversión en adaptación al cambio climático | BK8: Inversión en adaptación al cambio climático % del PIB | BL8: Pago de Intereses | BM8: Pago de Intereses % del PIB | BN8: Balance Primario | BO8: Balance Primario % del PIB | BP8: Balance Total | BQ8: Balance Total % del PIB | BR8: Deuda Bruta (R$ Milhões) | BS8: Deuda Bruta % del PIB
B9: 1995Q1 | P9: 4.3297326 | S9: 70.61 | T9: 0.9056 | U9: 186146 | V9: -5711.0186 | W9: =V9/U9*100 -> -3.0680319 | X9: 1.7698813 | Y9: =X9/U9*100 -> 0.00095080277 | Z9: -5275.1774 | AA9: =Z9/U9*100 -> -2.8338924 | AB9: 434.07126 | AC9: =AB9/U9*100 -> 0.23318861 | AD9: 33742 | AE9: 5.5687403 | AH9: 519.413 | AI9: =AH9/U9*100 -> 0.27903527
B10: 1995Q2 | P10: 7.540996 | S10: 59.21 | T10: 0.9186 | U10: 192551 | V10: -6656.6475 | W10: =V10/U10*100 -> -3.4570828 | X10: 5.5771912 | Y10: =X10/U10*100 -> 0.0028964748 | Z10: -5946.1333 | AA10: =Z10/U10*100 -> -3.0880823 | AB10: 704.93699 | AC10: =AB10/U10*100 -> 0.36610404 | AD10: 33512 | AE10: 5.0244611 | AH10: 1008.784 | AI10: =AH10/U10*100 -> 0.52390484
B11: 1995Q3 | P11: 4.3965487 | S11: 43.93 | T11: 0.9543 | U11: 197782 | V11: -2421.4626 | W11: =V11/U11*100 -> -1.2243089 | X11: 4.659988 | Y11: =X11/U11*100 -> 0.0023561234 | Z11: -1169.2633 | AA11: =Z11/U11*100 -> -0.59118791 | AB11: 1247.5393 | AC11: =AB11/U11*100 -> 0.63076485 | AD11: 48713 | AE11: 6.7486167 | AH11: 1458.417 | AI11: =AH11/U11*100 -> 0.73738611
B12: 1995Q4 | P12: 4.5062071 | S12: 36.24 | T12: 0.96979 | U12: 194256 | V12: -3923.2933 | W12: =V12/U12*100 -> -2.019651 | X12: 6.0067728 | Y12: =X12/U12*100 -> 0.0030921942 | Z12: -4096.6753 | AA12: =Z12/U12*100 -> -2.1089054 | AB12: -179.38879 | AC12: =AB12/U12*100 -> -0.092346591 | AD12: 51840 | AE12: 6.7260472 | AH12: 1396.808 | AI12: =AH12/U12*100 -> 0.71905527
B13: 1996Q1 | C13: 189323.3 | H13: 35403.156 | I13: =H13/C13*100 -> 18.699841 | J13: 125685.05 | K13: =J13/C13*100 -> 66.386465 | L13: 14772.806 | M13: =L13/C13*100 -> 7.8029519 | N13: 12305.881 | O13: =N13/C13*100 -> 6.4999296 | P13: 2.7422583 | S13: 29.06 | T13: 0.9877 | U13: 199236 | V13: -3524.9065 | W13: =V13/U13*100 -> -1.7692116 | X13: 2.218255 | Y13: =X13/U13*100 -> 0.0011133806 | Z13: -4736.5343 | AA13: =Z13/U13*100 -> -2.3773486 | AB13: -1213.8461 | AC13: =AB13/U13*100 -> -0.60925039 | AD13: 55753 | AE13: 7.1129398 | AH13: 1624.533 | AI13: =AH13/U13*100 -> 0.81538126
B14: 1996Q2 | C14: 204610.73 | G14: 1.2870521 | H14: 39326.084 | I14: =H14/C14*100 -> 19.219952 | J14: 132510.86 | K14: =J14/C14*100 -> 64.762421 | L14: 17470.476 | M14: =L14/C14*100 -> 8.5383971 | N14: 14576.312 | O14: =N14/C14*100 -> 7.1239234 | P14: 3.714945 | S14: 24.55 | T14: 1.00285 | U14: 207745 | V14: -4314.8567 | W14: =V14/U14*100 -> -2.0769967 | X14: 21.296416 | Y14: =X14/U14*100 -> 0.010251229 | Z14: -4084.6676 | AA14: =Z14/U14*100 -> -1.966193 | AB14: 208.8927 | AC14: =AB14/U14*100 -> 0.10055246 | AD14: 59997 | AE14: 7.5088327 | AH14: 3731.371 | AI14: =AH14/U14*100 -> 1.7961304
B15: 1996Q3 | C15: 221513.23 | G15: 3.4533084 | H15: 41417.571 | I15: =H15/C15*100 -> 18.697561 | J15: 142658.33 | K15: =J15/C15*100 -> 64.401719 | L15: 20927.58 | M15: =L15/C15*100 -> 9.4475531 | N15: 15560.475 | O15: =N15/C15*100 -> 7.0246255 | P15: 1.7075967 | S15: 23.45 | T15: 1.02025 | U15: 224469 | V15: -5863.0108 | W15: =V15/U15*100 -> -2.6119468 | X15: 5.9151599 | Y15: =X15/U15*100 -> 0.002635179 | Z15: -5766.2799 | AA15: =Z15/U15*100 -> -2.5688536 | AB15: 90.815734 | AC15: =AB15/U15*100 -> 0.040458029 | AD15: 58775 | AE15: 7.118151 | AH15: 1472.075 | AI15: =AH15/U15*100 -> 0.65580325
B16: 1996Q4 | C16: 239316.35 | G16: -0.73454351 | H16: 43186.714 | I16: =H16/C16*100 -> 18.045869 | J16: 156087.5 | K16: =J16/C16*100 -> 65.222247 | L16: 22949.1 | M16: =L16/C16*100 -> 9.5894411 | N16: 15084.715 | O16: =N16/C16*100 -> 6.3032532 | P16: 1.0945657 | S16: 22.27 | T16: 1.03916 | U16: 219568 | V16: -10140.254 | W16: =V16/U16*100 -> -4.618275 | X16: 17.157526 | Y16: =X16/U16*100 -> 0.0078142198 | Z16: -11008.847 | AA16: =Z16/U16*100 -> -5.0138668 | AB16: -885.75071 | AC16: =AB16/U16*100 -> -0.4034061 | AD16: 60110 | AE16: 7.0633054 | AH16: 3963.708 | AI16: =AH16/U16*100 -> 1.8052303
B17: 1997Q1 | C17: 219117.05 | G17: 1.0080695 | H17: 42696.635 | I17: =H17/C17*100 -> 19.485766 | J17: 147807.94 | K17: =J17/C17*100 -> 67.456159 | L17: 19333.246 | M17: =L17/C17*100 -> 8.8232505 | N17: 13162.001 | O17: =N17/C17*100 -> 6.0068356 | P17: 2.2050409 | S17: 21.25 | T17: 1.05972 | U17: 208043 | V17: -4994.6999 | W17: =V17/U17*100 -> -2.4008017 | X17: 2.7593971 | Y17: =X17/U17*100 -> 0.001326359 | Z17: -5836.2198 | AA17: =Z17/U17*100 -> -2.805295 | AB17: -844.27926 | AC17: =AB17/U17*100 -> -0.40581959 | AD17: 58980 | AE17: 6.8595354 | AH17: 3019.1588 | AI17: =AH17/U17*100 -> 1.4512186
B18: 1997Q2 | C18: 232889.54 | G18: 0.54071695 | H18: 46189.458 | I18: =H18/C18*100 -> 19.833204 | J18: 154446.53 | K18: =J18/C18*100 -> 66.317503 | L18: 22570.114 | M18: =L18/C18*100 -> 9.6913383 | N18: 17401.764 | O18: =N18/C18*100 -> 7.4721106 | P18: 1.8402354 | S18: 20.12 | T18: 1.07642 | U18: 218405 | V18: -8235.726 | W18: =V18/U18*100 -> -3.7708505 | X18: 30.054631 | Y18: =X18/U18*100 -> 0.013760963 | Z18: -9155.7773 | AA18: =Z18/U18*100 -> -4.1921097 | AB18: -950.1059 | AC18: =AB18/U18*100 -> -0.43502022 | AD18: 57615 | AE18: 6.618724 | AH18: 4768.614 | AI18: =AH18/U18*100 -> 2.1833813
B19: 1997Q3 | C19: 246178.48 | G19: 1.0877811 | H19: 47287.134 | I19: =H19/C19*100 -> 19.208476 | J19: 157597.81 | K19: =J19/C19*100 -> 64.017704 | L19: 25171.21 | M19: =L19/C19*100 -> 10.224781 | N19: 18528.583 | O19: =N19/C19*100 -> 7.5264835 | P19: 0.26005328 | S19: 19.93 | T19: 1.0952 | U19: 229146 | V19: -7659.8693 | W19: =V19/U19*100 -> -3.3427899 | X19: 28.433883 | Y19: =X19/U19*100 -> 0.012408631 | Z19: -5934.6341 | AA19: =Z19/U19*100 -> -2.5898921 | AB19: 1696.8013 | AC19: =AB19/U19*100 -> 0.74048918 | AD19: 61931 | AE19: 7.0765184 | AH19: 4836.8813 | AI19: =AH19/U19*100 -> 2.1108295
B20: 1997Q4 | C20: 253904.12 | G20: 1.0307259 | H20: 45893.849 | I20: =H20/C20*100 -> 18.075267 | J20: 161953.64 | K20: =J20/C20*100 -> 63.785354 | L20: 24255.155 | M20: =L20/C20*100 -> 9.5528795 | N20: 17398.225 | O20: =N20/C20*100 -> 6.8522815 | P20: 0.83155845 | S20: 34.62 | T20: 1.1152 | U20: 227687 | V20: -11243.068 | W20: =V20/U20*100 -> -4.9379489 | X20: 22.735102 | Y20: =X20/U20*100 -> 0.0099852439 | Z20: -11576.291 | AA20: =Z20/U20*100 -> -5.0843003 | AB20: -355.95838 | AC20: =AB20/U20*100 -> -0.15633672 | AD20: 52173 | AE20: 5.9067273 | AH20: 6368.2802 | AI20: =AH20/U20*100 -> 2.796945
B21: 1998Q1 | C21: 235700.7 | G21: -1.9946134 | H21: 45594.777 | I21: =H21/C21*100 -> 19.344353 | J21: 157102.91 | K21: =J21/C21*100 -> 66.653561 | L21: 21714.344 | M21: =L21/C21*100 -> 9.2126769 | N21: 16098.855 | O21: =N21/C21*100 -> 6.8302108 | P21: 1.5169471 | S21: 24.5 | T21: 1.13556 | U21: 204708 | V21: -6475.7718 | W21: =V21/U21*100 -> -3.163419 | X21: 8.7301072 | Y21: =X21/U21*100 -> 0.0042646634 | Z21: -6855.639 | AA21: =Z21/U21*100 -> -3.3489844 | AB21: -388.59731 | AC21: =AB21/U21*100 -> -0.18983005 | AD21: 68594 | AE21: 7.7952511 | AH21: 3958.882 | AI21: =AH21/U21*100 -> 1.9339166
B22: 1998Q2 | C22: 251935.88 | G22: 1.6450158 | H22: 48379.307 | I22: =H22/C22*100 -> 19.203024 | J22: 159193.94 | K22: =J22/C22*100 -> 63.188278 | L22: 22895.701 | M22: =L22/C22*100 -> 9.0879081 | N22: 18804.595 | O22: =N22/C22*100 -> 7.4640402 | P22: 0.76087404 | S22: 21.04 | T22: 1.156 | U22: 216187 | V22: -7731.2546 | W22: =V22/U22*100 -> -3.5761885 | X22: 26.530834 | Y22: =X22/U22*100 -> 0.012272169 | Z22: -10856.78 | AA22: =Z22/U22*100 -> -5.0219394 | AB22: -3152.0564 | AC22: =AB22/U22*100 -> -1.4580231 | AD22: 70898 | AE22: 8.0774454 | AH22: 6295.0629 | AI22: =AH22/U22*100 -> 2.91186
B23: 1998Q3 | C23: 258043.29 | G23: -0.08650102 | H23: 47636.032 | I23: =H23/C23*100 -> 18.460481 | J23: 163447.31 | K23: =J23/C23*100 -> 63.341043 | L23: 25366.179 | M23: =L23/C23*100 -> 9.8302031 | N23: 18785.814 | O23: =N23/C23*100 -> 7.2801017 | P23: -0.84781572 | S23: 27.57 | T23: 1.18331 | U23: 224265 | V23: -9080.6987 | W23: =V23/U23*100 -> -4.0490931 | X23: 4.6231372 | Y23: =X23/U23*100 -> 0.0020614618 | Z23: -8358.8136 | AA23: =Z23/U23*100 -> -3.7272038 | AB23: 717.26197 | AC23: =AB23/U23*100 -> 0.31982787 | AD23: 45811 | AE23: 5.2484571 | AH23: 9989.9028 | AI23: =AH23/U23*100 -> 4.4545082
B24: 1998Q4 | C24: 256671.15 | G24: -1.0014589 | H24: 44249.303 | I24: =H24/C24*100 -> 17.239687 | J24: 163186.84 | K24: =J24/C24*100 -> 63.578178 | L24: 24325.808 | M24: =L24/C24*100 -> 9.4774217 | N24: 16781.028 | O24: =N24/C24*100 -> 6.5379487 | P24: 0.22957535 | S24: 26.27 | T24: 1.20771 | U24: 218712 | V24: -11705.155 | W24: =V24/U24*100 -> -5.3518577 | X24: 10.542422 | Y24: =X24/U24*100 -> 0.0048202302 | Z24: -10771.166 | AA24: =Z24/U24*100 -> -4.9248171 | AB24: 923.44678 | AC24: =AB24/U24*100 -> 0.42222045 | AD24: 44556 | AE24: 5.1577085 | AH24: 8611.7623 | AI24: =AH24/U24*100 -> 3.9374896
B25: 1999Q1 | C25: 250667.99 | G25: 0.1417472 | H25: 44120.584 | I25: =H25/C25*100 -> 17.601204 | J25: 164892.67 | K25: =J25/C25*100 -> 65.781302 | L25: 25846.744 | M25: =L25/C25*100 -> 10.311146 | N25: 22153.374 | O25: =N25/C25*100 -> 8.8377353 | P25: 2.8768345 | Q25: 42 | S25: 32.88 | T25: 1.80721 | U25: 141714 | V25: -5841.7028 | W25: =V25/U25*100 -> -4.1221777 | X25: 5.8240148 | Y25: =X25/U25*100 -> 0.0041096962 | Z25: -5196.7803 | AA25: =Z25/U25*100 -> -3.6670902 | AB25: 639.09855 | AC25: =AB25/U25*100 -> 0.45097771 | AD25: 33848 | AE25: 4.2263616 | AH25: 7599.044 | AI25: =AH25/U25*100 -> 5.3622394
B26: 1999Q2 | C26: 268708.93 | G26: 0.42404654 | H26: 47152.458 | I26: =H26/C26*100 -> 17.547782 | J26: 170252.07 | K26: =J26/C26*100 -> 63.359291 | L26: 29000.694 | M26: =L26/C26*100 -> 10.792605 | N26: 24727.754 | O26: =N26/C26*100 -> 9.202431 | P26: 1.053228 | Q26: 21 | S26: 19.55 | T26: 1.77436 | U26: 148541 | V26: -7494.84 | W26: =V26/U26*100 -> -5.0456372 | X26: 35.541492 | Y26: =X26/U26*100 -> 0.023927059 | Z26: -7962.0148 | AA26: =Z26/U26*100 -> -5.3601462 | AB26: -502.71633 | AC26: =AB26/U26*100 -> -0.33843607 | AD26: 41346 | AE26: 5.6388701 | AH26: 5472.205 | AI26: =AH26/U26*100 -> 3.6839694
B27: 1999Q3 | C27: 274125.56 | G27: 0.11487801 | H27: 46383.161 | I27: =H27/C27*100 -> 16.920407 | J27: 178811.44 | K27: =J27/C27*100 -> 65.229759 | L27: 32971.23 | M27: =L27/C27*100 -> 12.027784 | N27: 27646.22 | O27: =N27/C27*100 -> 10.08524 | P27: 1.9710413 | Q27: 19 | S27: 18.92 | T27: 1.90375 | U27: 154115 | V27: -5275.6267 | W27: =V27/U27*100 -> -3.4231753 | X27: 2.7351714 | Y27: =X27/U27*100 -> 0.00177476 | Z27: -4609.8031 | AA27: =Z27/U27*100 -> -2.991145 | AB27: 663.08837 | AC27: =AB27/U27*100 -> 0.43025557 | AD27: 42562 | AE27: 6.418814 | AH27: 8996.429 | AI27: =AH27/U27*100 -> 5.8374779
B28: 1999Q4 | C28: 294207.98 | G28: 1.3727965 | H28: 47431.808 | I28: =H28/C28*100 -> 16.121864 | J28: 189576.24 | K28: =J28/C28*100 -> 64.436132 | L28: 36368.152 | M28: =L28/C28*100 -> 12.361375 | N28: 29511.051 | O28: =N28/C28*100 -> 10.030677 | P28: 2.7642108 | Q28: 19 | S28: 18.55 | T28: 1.81568 | U28: 154920 | V28: -8171.4729 | W28: =V28/U28*100 -> -5.2746404 | X28: 16.576248 | Y28: =X28/U28*100 -> 0.010699876 | Z28: -6789.4768 | AA28: =Z28/U28*100 -> -4.3825696 | AB28: 1365.4199 | AC28: =AB28/U28*100 -> 0.88137096 | AD28: 36342 | AE28: 6.0641759 | AH28: 6317.9976 | AI28: =AH28/U28*100 -> 4.0782324
B29: 2000Q1 | C29: 276926.91 | G29: 1.0713041 | H29: 56886.923 | I29: =H29/C29*100 -> 20.542216 | J29: 176025.23 | K29: =J29/C29*100 -> 63.563786 | L29: 31107.005 | M29: =L29/C29*100 -> 11.23293 | N29: 26401.853 | O29: =N29/C29*100 -> 9.5338707 | P29: 0.97257894 | Q29: 18.5 | S29: 18.15 | T29: 1.73742 | U29: 154920 | V29: -4405.445 | W29: =V29/U29*100 -> -2.8436903 | X29: 3.1392793 | Y29: =X29/U29*100 -> 0.0020263873 | Z29: -5037.4009 | AA29: =Z29/U29*100 -> -3.2516143 | AB29: -635.09522 | AC29: =AB29/U29*100 -> -0.40995044 | AD29: 39200 | AE29: 6.4000418 | AH29: 6947.94 | AI29: =AH29/U29*100 -> 4.4848567
B30: 2000Q2 | C30: 292788.56 | G30: 1.3388979 | H30: 53911.079 | I30: =H30/C30*100 -> 18.412973 | J30: 189995.88 | K30: =J30/C30*100 -> 64.89184 | L30: 34983.081 | M30: =L30/C30*100 -> 11.94824 | N30: 30238.766 | O30: =N30/C30*100 -> 10.327851 | P30: 0.6614672 | Q30: 17.5 | S30: 17.51 | T30: 1.81302 | U30: 161772 | V30: -7485.5118 | W30: =V30/U30*100 -> -4.6271986 | X30: 33.233271 | Y30: =X30/U30*100 -> 0.020543277 | Z30: -5540.7745 | AA30: =Z30/U30*100 -> -3.4250516 | AB30: 1911.504 | AC30: =AB30/U30*100 -> 1.1816037 | AD30: 28265 | AE30: 4.5171457 | AH30: 6472.825 | AI30: =AH30/U30*100 -> 4.0012023
B31: 2000Q3 | C31: 308895.8 | G31: 1.3486864 | H31: 53878.575 | I31: =H31/C31*100 -> 17.442314 | J31: 200011.59 | K31: =J31/C31*100 -> 64.750505 | L31: 40155.473 | M31: =L31/C31*100 -> 12.999683 | N31: 33767.675 | O31: =N31/C31*100 -> 10.931736 | P31: 3.1778375 | Q31: 16.5 | S31: 16.05 | T31: 1.85087 | U31: 169058 | V31: -4956.6518 | W31: =V31/U31*100 -> -2.9319238 | X31: 57.037115 | Y31: =X31/U31*100 -> 0.033738194 | Z31: -3196.8393 | AA31: =Z31/U31*100 -> -1.8909719 | AB31: 1702.7753 | AC31: =AB31/U31*100 -> 1.0072137 | AD31: 31431 | AE31: 4.9059578 | AH31: 9442.517 | AI31: =AH31/U31*100 -> 5.5853713
B32: 2000Q4 | C32: 320480.81 | G32: 1.1325354 | H32: 54811.088 | I32: =H32/C32*100 -> 17.102768 | J32: 208493.25 | K32: =J32/C32*100 -> 65.056392 | L32: 43061.948 | M32: =L32/C32*100 -> 13.43667 | N32: 31755.782 | O32: =N32/C32*100 -> 9.9087938 | P32: 1.0528654 | Q32: 15.75 | S32: 15.74 | T32: 1.95728 | U32: 169958 | V32: -9683.2403 | W32: =V32/U32*100 -> -5.6974313 | X32: 33.409251 | Y32: =X32/U32*100 -> 0.019657357 | Z32: -6649.4081 | AA32: =Z32/U32*100 -> -3.9123831 | AB32: 3000.423 | AC32: =AB32/U32*100 -> 1.7653908 | AD32: 33011 | AE32: 5.0344056 | AH32: 10131.437 | AI32: =AH32/U32*100 -> 5.9611414
B33: 2001Q1 | C33: 312469.82 | G33: 0.27338372 | H33: 61689.234 | I33: =H33/C33*100 -> 19.742462 | J33: 203369.32 | K33: =J33/C33*100 -> 65.084468 | L33: 42901.626 | M33: =L33/C33*100 -> 13.729846 | N33: 33576.475 | O33: =N33/C33*100 -> 10.74551 | P33: 1.4167167 | Q33: 15.75 | S33: 15.14 | T33: 2.12975 | U33: 135716 | V33: -7117.6395 | W33: =V33/U33*100 -> -5.2445102 | X33: 11.869906 | Y33: =X33/U33*100 -> 0.0087461358 | Z33: -5855.0117 | AA33: =Z33/U33*100 -> -4.3141647 | AB33: 1250.7579 | AC33: =AB33/U33*100 -> 0.92159942 | AD33: 34407 | AE33: 5.405622 | AH33: 4736.5576 | AI33: =AH33/U33*100 -> 3.490051
B34: 2001Q2 | C34: 323723.56 | G34: -0.37944376 | H34: 62066.886 | I34: =H34/C34*100 -> 19.172805 | J34: 210283.8 | K34: =J34/C34*100 -> 64.957831 | L34: 48577.436 | M34: =L34/C34*100 -> 15.005839 | N34: 40837.156 | O34: =N34/C34*100 -> 12.614824 | P34: 1.5175831 | Q34: 18.25 | S34: 17.18 | T34: 2.36703 | U34: 140033 | V34: -7114.8226 | W34: =V34/U34*100 -> -5.0808185 | X34: 64.390781 | Y34: =X34/U34*100 -> 0.045982576 | Z34: -6503.3097 | AA34: =Z34/U34*100 -> -4.6441265 | AB34: 547.12212 | AC34: =AB34/U34*100 -> 0.39070942 | AD34: 37318 | AE34: 6.070287 | AH34: 5161.7115 | AI34: =AH34/U34*100 -> 3.6860679
B35: 2001Q3 | C35: 332524.45 | G35: -0.45837951 | H35: 60427.389 | I35: =H35/C35*100 -> 18.172315 | J35: 211485.55 | K35: =J35/C35*100 -> 63.600002 | L35: 51522.557 | M35: =L35/C35*100 -> 15.494367 | N35: 45700.995 | O35: =N35/C35*100 -> 13.74365 | P35: 2.3245617 | Q35: 19 | S35: 18.83 | T35: 2.71701 | U35: 142787 | V35: -4455.1805 | W35: =V35/U35*100 -> -3.1201583 | X35: 15.769595 | Y35: =X35/U35*100 -> 0.011044139 | Z35: -5481.9939 | AA35: =Z35/U35*100 -> -3.8392808 | AB35: -1042.583 | AC35: =AB35/U35*100 -> -0.73016658 | AD35: 40054 | AE35: 6.8061866 | AH35: 5382.0797 | AI35: =AH35/U35*100 -> 3.7693065
B36: 2001Q4 | C36: 347037.64 | G36: -0.4482184 | H36: 58153.471 | I36: =H36/C36*100 -> 16.757108 | J36: 218362 | K36: =J36/C36*100 -> 62.921705 | L36: 48632.565 | M36: =L36/C36*100 -> 14.013628 | N36: 42666.833 | O36: =N36/C36*100 -> 12.294584 | P36: 2.2063467 | Q36: 19 | S36: 18.54 | T36: 2.32599 | U36: 141025 | V36: -6202.4346 | W36: =V36/U36*100 -> -4.39811 | X36: 13.654324 | Y36: =X36/U36*100 -> 0.0096822008 | Z36: -5169.824 | AA36: =Z36/U36*100 -> -3.6658919 | AB36: 1018.9563 | AC36: =AB36/U36*100 -> 0.72253591 | AD36: 35866 | AE36: 6.4096676 | AH36: 7945.4976 | AI36: =AH36/U36*100 -> 5.6341057
... B60: 2007Q4 | C60: 726339.31 | G60: 1.4668588 | H60: 131177.44 | I60: =H60/C60*100 -> 18.060077 | J60: 432651.75 | K60: =J60/C60*100 -> 59.566066 | L60: 86062.832 | M60: =L60/C60*100 -> 11.848847 | N60: 92082.932 | O60: =N60/C60*100 -> 12.677674 | P60: 1.4261792 | Q60: 11.25 | S60: 10.32 | T60: 1.79032 | U60: 402481 | V60: -3372.7424 | W60: =V60/U60*100 -> -0.83798799 | X60: 72.54367 | Y60: =X60/U60*100 -> 0.018024123 | Z60: -2079.5499 | AA60: =Z60/U60*100 -> -0.51668275 | AB60: 1220.6489 | AC60: =AB60/U60*100 -> 0.30328112 | AD60: 180334 | AE60: 12.910537 | AH60: 9312.5143 | AI60: =AH60/U60*100 -> 2.3137774
B61: 2008Q1 | C61: 712055.25 | G61: 1.3305789 | H61: 132371.45 | I61: =H61/C61*100 -> 18.590054 | J61: 433753.15 | K61: =J61/C61*100 -> 60.915659 | L61: 86426.453 | M61: =L61/C61*100 -> 12.137605 | N61: 80459.148 | O61: =N61/C61*100 -> 11.299565 | P61: 1.5177807 | Q61: 11.25 | S61: 10.35 | T61: 1.73052 | U61: 404598 | V61: -12155.313 | W61: =V61/U61*100 -> -3.0042939 | X61: 18.616155 | Y61: =X61/U61*100 -> 0.0046011485 | Z61: -13957.967 | AA61: =Z61/U61*100 -> -3.4498359 | AB61: -1821.2702 | AC61: =AB61/U61*100 -> -0.45014316 | AD61: 195232 | AE61: 12.994113 | AH61: 10181.419 | AI61: =AH61/U61*100 -> 2.5164285 | BR61: ='BCB-DBGG-trimestral'!B3 -> 1599048.5 | BS61: ='BCB-DBGG-trimestral'!C3 -> 57.090623
B62: 2008Q2 | C62: 769525.16 | G62: 2.0311179 | H62: 147732.51 | I62: =H62/C62*100 -> 19.197879 | J62: 456472.74 | K62: =J62/C62*100 -> 59.318754 | L62: 98761.08 | M62: =L62/C62*100 -> 12.834029 | N62: 98392.591 | O62: =N62/C62*100 -> 12.786144 | P62: 2.0944221 | Q62: 12.25 | S62: 11.44 | T62: 1.60444 | U62: 457169 | V62: -8114.0063 | W62: =V62/U62*100 -> -1.7748374 | X62: 44.527334 | Y62: =X62/U62*100 -> 0.0097397974 | Z62: -6043.4203 | AA62: =Z62/U62*100 -> -1.3219226 | AB62: 2026.0586 | AC62: =AB62/U62*100 -> 0.44317498 | AD62: 200827 | AE62: 12.376414 | AH62: 9966.4043 | AI62: =AH62/U62*100 -> 2.1800263 | BR62: ='BCB-DBGG-trimestral'!B4 -> 1612136.7 | BS62: ='BCB-DBGG-trimestral'!C4 -> 55.595415
B63: 2008Q3 | C63: 812602.58 | G63: 1.5348641 | H63: 168885.98 | I63: =H63/C63*100 -> 20.783343 | J63: 480468.43 | K63: =J63/C63*100 -> 59.127111 | L63: 114296.52 | M63: =L63/C63*100 -> 14.065489 | N63: 115435.04 | O63: =N63/C63*100 -> 14.205596 | P63: 1.0734116 | Q63: 13.75 | S63: 12.42 | T63: 1.86427 | U63: 479466 | V63: -8637.0573 | W63: =V63/U63*100 -> -1.801391 | X63: 60.107773 | Y63: =X63/U63*100 -> 0.012536399 | Z63: -8770.7197 | AA63: =Z63/U63*100 -> -1.8292683 | AB63: -193.77017 | AC63: =AB63/U63*100 -> -0.040413746 | AD63: 206494 | AE63: 11.842194 | AH63: 15585.27 | AI63: =AH63/U63*100 -> 3.2505476 | BR63: ='BCB-DBGG-trimestral'!B5 -> 1656166.5 | BS63: ='BCB-DBGG-trimestral'!C5 -> 54.830469
B64: 2008Q4 | C64: 815620.1 | G64: -3.743358 | H64: 153855.63 | I64: =H64/C64*100 -> 18.863639 | J64: 486815.73 | K64: =J64/C64*100 -> 59.686578 | L64: 127291.91 | M64: =L64/C64*100 -> 15.606765 | N64: 126593.99 | O64: =N64/C64*100 -> 15.521195 | P64: 1.0941623 | Q64: 13.75 | S64: 12.5 | T64: 2.36636 | U64: 351914 | V64: -6695.3509 | W64: =V64/U64*100 -> -1.9025532 | X64: 28.845365 | Y64: =X64/U64*100 -> 0.0081967085 | Z64: 4632.1964 | AA64: =Z64/U64*100 -> 1.3162865 | AB64: 11298.702 | AC64: =AB64/U64*100 -> 3.2106429 | AD64: 193783 | AE64: 11.445137 | AH64: 14983.309 | AI64: =AH64/U64*100 -> 4.257662 | BR64: ='BCB-DBGG-trimestral'!B6 -> 1740887.8 | BS64: ='BCB-DBGG-trimestral'!C6 -> 55.980645
B65: 2009Q1 | C65: 756127.09 | G65: -1.3586991 | H65: 134944.75 | I65: =H65/C65*100 -> 17.846835 | J65: 474263.58 | K65: =J65/C65*100 -> 62.722734 | L65: 93767.449 | M65: =L65/C65*100 -> 12.401017 | N65: 87414.684 | O65: =N65/C65*100 -> 11.560845 | P65: 1.2344185 | Q65: 11.25 | S65: 10.47 | T65: 2.26828 | U65: 320254 | V65: -6412.1017 | W65: =V65/U65*100 -> -2.0021925 | X65: 26.361606 | Y65: =X65/U65*100 -> 0.0082314682 | Z65: -4704.8754 | AA65: =Z65/U65*100 -> -1.4691075 | AB65: 1680.8646 | AC65: =AB65/U65*100 -> 0.52485359 | AD65: 190388 | AE65: 11.83414 | AH65: 5670.3621 | AI65: =AH65/U65*100 -> 1.7705828 | BR65: ='BCB-DBGG-trimestral'!B7 -> 1812527.1 | BS65: ='BCB-DBGG-trimestral'!C7 -> 57.469847
B66: 2009Q2 | C66: 803577.49 | G66: 1.7878377 | H66: 147361.7 | I66: =H66/C66*100 -> 18.338206 | J66: 504219.99 | K66: =J66/C66*100 -> 62.746903 | L66: 88904.311 | M66: =L66/C66*100 -> 11.063564 | N66: 93899.818 | O66: =N66/C66*100 -> 11.685223 | P66: 1.3156592 | Q66: 9.25 | S66: 8.74 | T66: 1.96863 | U66: 380565 | V66: -3030.2091 | W66: =V66/U66*100 -> -0.79623957 | X66: 76.441572 | Y66: =X66/U66*100 -> 0.020086338 | Z66: -1955.0872 | AA66: =Z66/U66*100 -> -0.5137328 | AB66: 998.68032 | AC66: =AB66/U66*100 -> 0.26242043 | AD66: 201467 | AE66: 13.148879 | AH66: 8225.4 | AI66: =AH66/U66*100 -> 2.1613653 | BR66: ='BCB-DBGG-trimestral'!B8 -> 1859801.5 | BS66: ='BCB-DBGG-trimestral'!C8 -> 58.338895
B67: 2009Q3 | C67: 852843.25 | G67: 2.3601913 | H67: 172381.63 | I67: =H67/C67*100 -> 20.212581 | J67: 534397.21 | K67: =J67/C67*100 -> 62.66066 | L67: 95863.413 | M67: =L67/C67*100 -> 11.240449 | N67: 92906.412 | O67: =N67/C67*100 -> 10.893727 | P67: 0.63125611 | Q67: 8.75 | S67: 8.21 | T67: 1.79845 | U67: 449297 | V67: -6580.4682 | W67: =V67/U67*100 -> -1.4646143 | X67: 29.411123 | Y67: =X67/U67*100 -> 0.0065460314 | Z67: -3100.8944 | AA67: =Z67/U67*100 -> -0.69016583 | AB67: 3450.1627 | AC67: =AB67/U67*100 -> 0.76790247 | AD67: 221629 | AE67: 14.755298 | AH67: 7577.1987 | AI67: =AH67/U67*100 -> 1.6864566 | BR67: ='BCB-DBGG-trimestral'!B9 -> 1962852.3 | BS67: ='BCB-DBGG-trimestral'!C9 -> 60.80391
...

Sheet Datos_Anuales
A2: Plantilla de datos para estimación de modelo FISLAC - Brasil
A4: Nota: por favor completar la información con la mayor cantidad de datos históricos disponibles
C7: Sector Real | P7: Sector Monetario | V7: Balanza de Pagos | AJ7: Sector Fiscal
B8: Años | C8: PIB Nominal | D8: PIB Real | E8: PIB potencial | F8: Brecha del PIB | G8: Crecimiento PIB Real | H8: Inversión Privada | I8: Inversión Privada % del PIB | J8: Consumo Privado | K8: Consumo Privado % del PIB | L8: Importaciones | M8: Importaciones % del PIB | N8: Exportaciones | O8: Exportaciones % del PIB | P8: Inflación (%) | Q8: Tasa de Política Monetaria (%) | R8: Tasa activa promedio (%) | S8: Tasa pasiva promedio (%) | T8: Tasa de Cambio (por Dólar) | U8: PIB Nominal (USD) | V8: Saldo Cuenta Corriente (USD) | W8: Saldo Cuenta Corriente % del PIB | X8: Saldo Cuenta Capital (USD) | Y8: Saldo Cuenta Capital % del PIB | Z8: Saldo Cuenta financiera (USD) | AA8: Saldo Cuenta financiera % del PIB | AB8: Errores y omisiones (USD) | AC8: Errores y omisiones % del PIB | AD8: Reservas Internacionales Netas (USD) | AE8: Reservas Internacionales Netas % del PIB | AF8: Remesas Internacionales (USD) | AG8: Remesas Internacionales % del PIB | AH8: Inversión extranjera directa (USD) | AI8: Inversión extranjera directa % del PIB | AJ8: Ingreso Fiscal (Total) | AK8: Ingreso Fiscal (Total) % del PIB | AL8: Ingreso por Materias Primas | AM8: Ingreso por Materias Primas % del PIB | AN8: Ingreso Tributario | AO8: Ingreso Tributario % del PIB | AP8: Ingreso Impuestos Consumo | AQ8: Ingreso Impuestos Consumo % del PIB | AR8: Ingreso Impuestos Renta Laboral | AS8: Ingreso Impuestos Renta Laboral % del PIB | AT8: Ingreso Impuestos Renta de capital | AU8: Ingreso Impuestos Renta de capital % del PIB | AV8: Ingreso Impuestos Renta de Empresas | AW8: Ingreso Impuestos Renta de Empresas % del PIB | AX8: Ingreso Otros | AY8: Ingreso Otros % del PIB | AZ8: Gasto Público Total | BA8: Gasto Público Total % del PIB | BB8: Gasto Público Primario | BC8: Gasto Público Primario % del PIB | BD8: Gasto Corriente Primario | BE8: Gasto Corriente Primario % del PIB | BF8: Gasto en atención a desastres naturales | BG8: Gasto en atención a desastres naturales % del PIB | BH8: Gasto de Capital | BI8: Gasto de Capital % del PIB | BJ8: Inversión en adaptación al cambio climático | BK8: Inversión en adaptación al cambio climático % del PIB | BL8: Pago de Intereses | BM8: Pago de Intereses % del PIB | BN8: Balance Primario | BO8: Balance Primario % del PIB | BP8: Balance Total | BQ8: Balance Total % del PIB | BR8: Deuda Bruta (R$ Milhões) | BS8: Deuda Bruta % del PIB
B9: 1981 | P9: 95.623044
B10: 1982 | P10: 104.79043
B11: 1983 | P11: 164.01202
B12: 1984 | P12: 215.26333
B13: 1985 | P13: 242.2298
B14: 1986 | P14: 79.664497
B15: 1987 | P15: 363.41152
B16: 1988 | P16: 980.21349
B17: 1989 | P17: 1972.9116
B18: 1990 | P18: 1620.9665 | U18: 469318 | AD18: 9973 | AE18: =AD18/U18*100 -> 2.1249984
B19: 1991 | P19: 472.7 | U19: 405679 | AD19: 9406 | AE19: =AD19/U19*100 -> 2.3185819
B20: 1992 | P20: 1119.1008 | S20: 1520.75 | U20: 387295 | AD20: 23754 | AE20: =AD20/U20*100 -> 6.1333092
B21: 1993 | P21: 2477.1471 | S21: 4730.51 | U21: 429685 | AD21: 32211 | AE21: =AD21/U21*100 -> 7.4964218
B22: 1994 | P22: 916.46 | S22: 49.99 | T22: 0.8518 | U22: 543087 | AD22: 38806 | AE22: =AD22/U22*100 -> 7.1454482
B23: 1995 | C23: 705991.55 | H23: 143219.55 | I23: =H23/C23*100 -> 20.286298 | J23: 449762.08 | K23: =J23/C23*100 -> 63.706439 | L23: 66755.631 | M23: =L23/C23*100 -> 9.455585 | N23: 53153.222 | O23: =N23/C23*100 -> 7.528875 | P23: 22.408162 | S23: 36.24 | T23: 0.96979 | U23: 770733 | V23: -18712.422 | W23: =V23/U23*100 -> -2.4278735 | X23: 18.013833 | Y23: =X23/U23*100 -> 0.0023372339 | Z23: -16487.249 | AA23: =Z23/U23*100 -> -2.1391648 | AB23: 2207.1588 | AC23: =AB23/U23*100 -> 0.28637139 | AD23: 51840 | AE23: =AD23/U23*100 -> 6.7260647 | AH23: 4383.422 | AI23: =AH23/U23*100 -> 0.56873418
B24: 1996 | C24: 854763.61 | G24: 2.2088641 | H24: 159333.52 | I24: =H24/C24*100 -> 18.640654 | J24: 556941.74 | K24: =J24/C24*100 -> 65.157399 | L24: 76119.963 | M24: =L24/C24*100 -> 8.9053818 | N24: 57527.383 | O24: =N24/C24*100 -> 6.7302097 | P24: 9.5649518 | S24: 22.27 | T24: 1.03916 | U24: 851019 | V24: -23843.028 | W24: =V24/U24*100 -> -2.8017034 | X24: 46.587357 | Y24: =X24/U24*100 -> 0.0054743028 | Z24: -25596.329 | AA24: =Z24/U24*100 -> -3.0077271 | AB24: -1799.8884 | AC24: =AB24/U24*100 -> -0.21149802 | AD24: 60110 | AE24: =AD24/U24*100 -> 7.0632971 | AH24: 10791.687 | AI24: =AH24/U24*100 -> 1.26809
B25: 1997 | C25: 952089.2 | G25: 3.394846 | H25: 182067.08 | I25: =H25/C25*100 -> 19.122901 | J25: 621805.93 | K25: =J25/C25*100 -> 65.30963 | L25: 91329.724 | M25: =L25/C25*100 -> 9.5925597 | N25: 66490.573 | O25: =N25/C25*100 -> 6.9836496 | P25: 5.2243185 | S25: 34.62 | T25: 1.1152 | U25: 883282 | V25: -32133.363 | W25: =V25/U25*100 -> -3.6379506 | X25: 83.983013 | Y25: =X25/U25*100 -> 0.0095080635 | Z25: -32502.922 | AA25: =Z25/U25*100 -> -3.6797899 | AB25: -453.54221 | AC25: =AB25/U25*100 -> -0.051347385 | AD25: 52173 | AE25: =AD25/U25*100 -> 5.9067206 | AH25: 18992.934 | AI25: =AH25/U25*100 -> 2.1502685 | AJ25: =HLOOKUP(B25,'RTN-2.2'!$A$5:$AC$164,2,0) -> 159012.38 | AK25: =HLOOKUP(B25,'RTN-2.2-A'!$A$5:$AC$164,2,0)*100 -> 16.701416 | AN25: =HLOOKUP(B25,'RTN-2.2'!$A$5:$AC$164,3,0) -> 101710.99 | AO25: =HLOOKUP(B25,'RTN-2.2-A'!$A$5:$AC$164,3,0)*100 -> 10.682927 | AR25: =HLOOKUP(B25,'RTN-2.2'!$A$5:$AC$164,15,0) -> 10105.371 | AS25: =HLOOKUP(B25,'RTN-2.2-A'!$A$5:$AC$164,15,0)*100 -> 1.0613891 | AT25: =HLOOKUP(B25,'RTN-2.2'!$A$5:$AC$164,16,0) -> 5009.8452 | AU25: =HLOOKUP(B25,'RTN-2.2-A'!$A$5:$AC$164,16,0)*100 -> 0.52619494 | AV25: =HLOOKUP(B25,'RTN-2.2'!$A$5:$AC$164,13,0) -> 12213.438 | AW25: =HLOOKUP(B25,'RTN-2.2-A'!$A$5:$AC$164,13,0)*100 -> 1.2828039 | AZ25: =HLOOKUP(B25,'RTN-2.2'!$A$5:$AC$164,59,0) -> 132968 | BA25: =HLOOKUP(B25,'RTN-2.2-A'!$A$5:$AC$164,59,0)*100 -> 13.965918 | BL25: =HLOOKUP(B25,'RTN-2.2'!$A$5:$AC$164,159,0)*(-1) -> 18931.52 | BM25: =HLOOKUP(B25,'RTN-2.2-A'!$A$5:$AC$164,159,0)*100*(-1) -> 1.9884187 | BN25: =HLOOKUP(B25,'RTN-2.2'!$A$5:$AC$164,151,0) -> 1800.7523 | BO25: =HLOOKUP(B25,'RTN-2.2-A'!$A$5:$AC$164,151,0)*100 -> 0.18913693
B26: 1998 | C26: 1002351 | G26: 0.3380979 | H26: 185859.42 | I26: =H26/C26*100 -> 18.542348 | J26: 642931.01 | K26: =J26/C26*100 -> 64.142301 | L26: 94302.032 | M26: =L26/C26*100 -> 9.4080846 | N26: 70470.292 | O26: =N26/C26*100 -> 7.0305003 | P26: 1.6549782 | S26: 26.27 | T26: 1.20771 | U26: 863872 | V26: -34992.88 | W26: =V26/U26*100 -> -4.050702 | X26: 50.4265 | Y26: =X26/U26*100 -> 0.0058372653 | Z26: -36842.399 | AA26: =Z26/U26*100 -> -4.2647983 | AB26: -1899.9449 | AC26: =AB26/U26*100 -> -0.21993362 | AD26: 44556 | AE26: =AD26/U26*100 -> 5.1577085 | AH26: 28855.61 | AI26: =AH26/U26*100 -> 3.3402645 | AJ26: =HLOOKUP(B26,'RTN-2.2'!$A$5:$AC$164,2,0) -> 183516.2 | AK26: =HLOOKUP(B26,'RTN-2.2-A'!$A$5:$AC$164,2,0)*100 -> 18.308577 | AN26: =HLOOKUP(B26,'RTN-2.2'!$A$5:$AC$164,3,0) -> 111752.41 | AO26: =HLOOKUP(B26,'RTN-2.2-A'!$A$5:$AC$164,3,0)*100 -> 11.14903 | AR26: =HLOOKUP(B26,'RTN-2.2'!$A$5:$AC$164,15,0) -> 11879.118 | AS26: =HLOOKUP(B26,'RTN-2.2-A'!$A$5:$AC$164,15,0)*100 -> 1.1851255 | AT26: =HLOOKUP(B26,'RTN-2.2'!$A$5:$AC$164,16,0) -> 11927.483 | AU26: =HLOOKUP(B26,'RTN-2.2-A'!$A$5:$AC$164,16,0)*100 -> 1.1899507 | AV26: =HLOOKUP(B26,'RTN-2.2'!$A$5:$AC$164,13,0) -> 11838.117 | AW26: =HLOOKUP(B26,'RTN-2.2-A'!$A$5:$AC$164,13,0)*100 -> 1.1810351 | AZ26: =HLOOKUP(B26,'RTN-2.2'!$A$5:$AC$164,59,0) -> 148782.88 | BA26: =HLOOKUP(B26,'RTN-2.2-A'!$A$5:$AC$164,59,0)*100 -> 14.843391 | BL26: =HLOOKUP(B26,'RTN-2.2'!$A$5:$AC$164,159,0)*(-1) -> 50141.5 | BM26: =HLOOKUP(B26,'RTN-2.2-A'!$A$5:$AC$164,159,0)*100*(-1) -> 5.0023894 | BN26: =HLOOKUP(B26,'RTN-2.2'!$A$5:$AC$164,151,0) -> 7577.0177 | BO26: =HLOOKUP(B26,'RTN-2.2-A'!$A$5:$AC$164,151,0)*100 -> 0.75592459
B27: 1999 | C27: 1087710.5 | G27: 0.46793757 | H27: 185088.01 | I27: =H27/C27*100 -> 17.016294 | J27: 703532.42 | K27: =J27/C27*100 -> 64.680119 | L27: 124186.82 | M27: =L27/C27*100 -> 11.417268 | N27: 104038.4 | O27: =N27/C27*100 -> 9.5648983 | P27: 8.9397888 | Q27: 19 | S27: 18.55 | T27: 1.81568 | U27: 599290 | V27: -26783.642 | W27: =V27/U27*100 -> -4.469229 | X27: 60.676927 | Y27: =X27/U27*100 -> 0.010124802 | Z27: -24558.075 | AA27: =Z27/U27*100 -> -4.0978616 | AB27: 2164.8905 | AC27: =AB27/U27*100 -> 0.36124255 | AD27: 36342 | AE27: =AD27/U27*100 -> 6.0641759 | AH27: 28385.676 | AI27: =AH27/U27*100 -> 4.7365509 | AJ27: =HLOOKUP(B27,'RTN-2.2'!$A$5:$AC$164,2,0) -> 209383.53 | AK27: =HLOOKUP(B27,'RTN-2.2-A'!$A$5:$AC$164,2,0)*100 -> 19.249932 | AN27: =HLOOKUP(B27,'RTN-2.2'!$A$5:$AC$164,3,0) -> 134315.24 | AO27: =HLOOKUP(B27,'RTN-2.2-A'!$A$5:$AC$164,3,0)*100 -> 12.348437 | AR27: =HLOOKUP(B27,'RTN-2.2'!$A$5:$AC$164,15,0) -> 11451.938 | AS27: =HLOOKUP(B27,'RTN-2.2-A'!$A$5:$AC$164,15,0)*100 -> 1.052848 | AT27: =HLOOKUP(B27,'RTN-2.2'!$A$5:$AC$164,16,0) -> 13623.401 | AU27: =HLOOKUP(B27,'RTN-2.2-A'!$A$5:$AC$164,16,0)*100 -> 1.2524841 | AV27: =HLOOKUP(B27,'RTN-2.2'!$A$5:$AC$164,13,0) -> 12760.411 | AW27: =HLOOKUP(B27,'RTN-2.2-A'!$A$5:$AC$164,13,0)*100 -> 1.173144 | AZ27: =HLOOKUP(B27,'RTN-2.2'!$A$5:$AC$164,59,0) -> 158679.81 | BA27: =HLOOKUP(B27,'RTN-2.2-A'!$A$5:$AC$164,59,0)*100 -> 14.588423 | BL27: =HLOOKUP(B27,'RTN-2.2'!$A$5:$AC$164,159,0)*(-1) -> 49008.09 | BM27: =HLOOKUP(B27,'RTN-2.2-A'!$A$5:$AC$164,159,0)*100*(-1) -> 4.5056189 | BN27: =HLOOKUP(B27,'RTN-2.2'!$A$5:$AC$164,151,0) -> 20164.293 | BO27: =HLOOKUP(B27,'RTN-2.2-A'!$A$5:$AC$164,151,0)*100 -> 1.853829
B28: 2000 | C28: 1199092.1 | G28: 4.3879494 | H28: 219487.66 | I28: =H28/C28*100 -> 18.304488 | J28: 774525.95 | K28: =J28/C28*100 -> 64.5927 | L28: 149307.51 | M28: =L28/C28*100 -> 12.451713 | N28: 122164.08 | O28: =N28/C28*100 -> 10.188048 | P28: 5.9745933 | Q28: 15.75 | S28: 15.74 | T28: 1.95728 | U28: 655707 | V28: -26530.849 | W28: =V28/U28*100 -> -4.0461439 | X28: 126.81892 | Y28: =X28/U28*100 -> 0.01934079 | Z28: -20424.423 | AA28: =Z28/U28*100 -> -3.1148703 | AB28: 5979.6071 | AC28: =AB28/U28*100 -> 0.91193279 | AD28: 33011 | AE28: =AD28/U28*100 -> 5.0344132 | AH28: 32994.719 | AI28: =AH28/U28*100 -> 5.0319302 | AJ28: =HLOOKUP(B28,'RTN-2.2'!$A$5:$AC$164,2,0) -> 235051.93 | AK28: =HLOOKUP(B28,'RTN-2.2-A'!$A$5:$AC$164,2,0)*100 -> 19.602492 | AN28: =HLOOKUP(B28,'RTN-2.2'!$A$5:$AC$164,3,0) -> 156187.72 | AO28: =HLOOKUP(B28,'RTN-2.2-A'!$A$5:$AC$164,3,0)*100 -> 13.025499 | AR28: =HLOOKUP(B28,'RTN-2.2'!$A$5:$AC$164,15,0) -> 13817.417 | AS28: =HLOOKUP(B28,'RTN-2.2-A'!$A$5:$AC$164,15,0)*100 -> 1.1523233 | AT28: =HLOOKUP(B28,'RTN-2.2'!$A$5:$AC$164,16,0) -> 10676.972 | AU28: =HLOOKUP(B28,'RTN-2.2-A'!$A$5:$AC$164,16,0)*100 -> 0.89042134 | AV28: =HLOOKUP(B28,'RTN-2.2'!$A$5:$AC$164,13,0) -> 17511.299 | AW28: =HLOOKUP(B28,'RTN-2.2-A'!$A$5:$AC$164,13,0)*100 -> 1.4603798 | AZ28: =HLOOKUP(B28,'RTN-2.2'!$A$5:$AC$164,59,0) -> 177372.06 | BA28: =HLOOKUP(B28,'RTN-2.2-A'!$A$5:$AC$164,59,0)*100 -> 14.792197 | BL28: =HLOOKUP(B28,'RTN-2.2'!$A$5:$AC$164,159,0)*(-1) -> 45447.03 | BM28: =HLOOKUP(B28,'RTN-2.2-A'!$A$5:$AC$164,159,0)*100*(-1) -> 3.7901201 | BN28: =HLOOKUP(B28,'RTN-2.2'!$A$5:$AC$164,151,0) -> 20982.204 | BO28: =HLOOKUP(B28,'RTN-2.2-A'!$A$5:$AC$164,151,0)*100 -> 1.749841
B29: 2001 | C29: 1315755.5 | G29: 1.3898964 | H29: 242336.98 | I29: =H29/C29*100 -> 18.418087 | J29: 843500.68 | K29: =J29/C29*100 -> 64.107708 | L29: 191634.18 | M29: =L29/C29*100 -> 14.564574 | N29: 162781.46 | O29: =N29/C29*100 -> 12.371711 | P29: 7.6734364 | Q29: 19 | S29: 18.54 | T29: 2.32599 | U29: 559563 | V29: -24890.077 | W29: =V29/U29*100 -> -4.4481278 | X29: 105.68461 | Y29: =X29/U29*100 -> 0.01888699 | Z29: -23010.139 | AA29: =Z29/U29*100 -> -4.1121624 | AB29: 1774.2533 | AC29: =AB29/U29*100 -> 0.31707838 | AD29: 35866 | AE29: =AD29/U29*100 -> 6.4096447 | AH29: 23225.846 | AI29: =AH29/U29*100 -> 4.1507116 | AJ29: =HLOOKUP(B29,'RTN-2.2'!$A$5:$AC$164,2,0) -> 270441.18 | AK29: =HLOOKUP(B29,'RTN-2.2-A'!$A$5:$AC$164,2,0)*100 -> 20.554061 | AN29: =HLOOKUP(B29,'RTN-2.2'!$A$5:$AC$164,3,0) -> 179218.17 | AO29: =HLOOKUP(B29,'RTN-2.2-A'!$A$5:$AC$164,3,0)*100 -> 13.620933 | AR29: =HLOOKUP(B29,'RTN-2.2'!$A$5:$AC$164,15,0) -> 16924.356 | AS29: =HLOOKUP(B29,'RTN-2.2-A'!$A$5:$AC$164,15,0)*100 -> 1.2862843 | AT29: =HLOOKUP(B29,'RTN-2.2'!$A$5:$AC$164,16,0) -> 15193.088 | AU29: =HLOOKUP(B29,'RTN-2.2-A'!$A$5:$AC$164,16,0)*100 -> 1.1547045 | AV29: =HLOOKUP(B29,'RTN-2.2'!$A$5:$AC$164,13,0) -> 16842.886 | AW29: =HLOOKUP(B29,'RTN-2.2-A'!$A$5:$AC$164,13,0)*100 -> 1.2800924 | AZ29: =HLOOKUP(B29,'RTN-2.2'!$A$5:$AC$164,59,0) -> 205643.18 | BA29: =HLOOKUP(B29,'RTN-2.2-A'!$A$5:$AC$164,59,0)*100 -> 15.629286 | BL29: =HLOOKUP(B29,'RTN-2.2'!$A$5:$AC$164,159,0)*(-1) -> 47253.044 | BM29: =HLOOKUP(B29,'RTN-2.2-A'!$A$5:$AC$164,159,0)*100*(-1) -> 3.5913242 | BN29: =HLOOKUP(B29,'RTN-2.2'!$A$5:$AC$164,151,0) -> 21737.1 | BO29: =HLOOKUP(B29,'RTN-2.2-A'!$A$5:$AC$164,151,0)*100 -> 1.6520623
B30: 2002 | C30: 1488787.3 | G30: 3.0534619 | H30: 266883.74 | I30: =H30/C30*100 -> 17.926251 | J30: 921536.01 | K30: =J30/C30*100 -> 61.898435 | L30: 199315.37 | M30: =L30/C30*100 -> 13.387767 | N30: 211863.21 | O30: =N30/C30*100 -> 14.23059 | P30: 12.530273 | Q30: 25 | S30: 22.66 | T30: 3.51755 | U30: 508101 | V30: -9407.0433 | W30: =V30/U30*100 -> -1.8514121 | X30: 79.278742 | Y30: =X30/U30*100 -> 0.015602949 | Z30: -6893.3476 | AA30: =Z30/U30*100 -> -1.3566884 | AB30: 2434.417 | AC30: =AB30/U30*100 -> 0.47912068 | AD30: 37823 | AE30: =AD30/U30*100 -> 7.4439924 | AH30: 16586.6 | AI30: =AH30/U30*100 -> 3.2644297 | AJ30: =HLOOKUP(B30,'RTN-2.2'!$A$5:$AC$164,2,0) -> 320056.45 | AK30: =HLOOKUP(B30,'RTN-2.2-A'!$A$5:$AC$164,2,0)*100 -> 21.497797 | AN30: =HLOOKUP(B30,'RTN-2.2'!$A$5:$AC$164,3,0) -> 219900.79 | AO30: =HLOOKUP(B30,'RTN-2.2-A'!$A$5:$AC$164,3,0)*100 -> 14.770465 | AR30: =HLOOKUP(B30,'RTN-2.2'!$A$5:$AC$164,15,0) -> 16413.73 | AS30: =HLOOKUP(B30,'RTN-2.2-A'!$A$5:$AC$164,15,0)*100 -> 1.10249 | AT30: =HLOOKUP(B30,'RTN-2.2'!$A$5:$AC$164,16,0) -> 16223.956 | AU30: =HLOOKUP(B30,'RTN-2.2-A'!$A$5:$AC$164,16,0)*100 -> 1.0897431 | AV30: =HLOOKUP(B30,'RTN-2.2'!$A$5:$AC$164,13,0) -> 33341.047 | AW30: =HLOOKUP(B30,'RTN-2.2-A'!$A$5:$AC$164,13,0)*100 -> 2.2394769 | AZ30: =HLOOKUP(B30,'RTN-2.2'!$A$5:$AC$164,59,0) -> 236461.07 | BA30: =HLOOKUP(B30,'RTN-2.2-A'!$A$5:$AC$164,59,0)*100 -> 15.882798 | BL30: =HLOOKUP(B30,'RTN-2.2'!$A$5:$AC$164,159,0)*(-1) -> 41948.248 | BM30: =HLOOKUP(B30,'RTN-2.2-A'!$A$5:$AC$164,159,0)*100*(-1) -> 2.817612 | BN30: =HLOOKUP(B30,'RTN-2.2'!$A$5:$AC$164,151,0) -> 31577.205 | BO30: =HLOOKUP(B30,'RTN-2.2-A'!$A$5:$AC$164,151,0)*100 -> 2.1210018
B31: 2003 | C31: 1717950.4 | G31: 1.140829 | H31: 285261.53 | I31: =H31/C31*100 -> 16.604759 | J31: 1062460.4 | K31: =J31/C31*100 -> 61.84465 | L31: 222639.52 | M31: =L31/C31*100 -> 12.959601 | N31: 260798.33 | O31: =N31/C31*100 -> 15.180784 | P31: 9.3005128 | Q31: 16.5 | S31: 15.56 | T31: 2.91157 | U31: 559465 | V31: 2193.173 | W31: =V31/U31*100 -> 0.39201255 | X31: 82.844955 | Y31: =X31/U31*100 -> 0.014807889 | Z31: 4360.9966 | AA31: =Z31/U31*100 -> 0.77949408 | AB31: 2084.9786 | AC31: =AB31/U31*100 -> 0.37267364 | AD31: 49296 | AE31: =AD31/U31*100 -> 8.8112751 | AH31: 10123.014 | AI31: =AH31/U31*100 -> 1.8094096 | AJ31: =HLOOKUP(B31,'RTN-2.2'!$A$5:$AC$164,2,0) -> 356131.53 | AK31: =HLOOKUP(B31,'RTN-2.2-A'!$A$5:$AC$164,2,0)*100 -> 20.730024 | AN31: =HLOOKUP(B31,'RTN-2.2'!$A$5:$AC$164,3,0) -> 242869.36 | AO31: =HLOOKUP(B31,'RTN-2.2-A'!$A$5:$AC$164,3,0)*100 -> 14.137158 | AR31: =HLOOKUP(B31,'RTN-2.2'!$A$5:$AC$164,15,0) -> 19622.902 | AS31: =HLOOKUP(B31,'RTN-2.2-A'!$A$5:$AC$164,15,0)*100 -> 1.1422275 | AT31: =HLOOKUP(B31,'RTN-2.2'!$A$5:$AC$164,16,0) -> 18859.928 | AU31: =HLOOKUP(B31,'RTN-2.2-A'!$A$5:$AC$164,16,0)*100 -> 1.0978156 | AV31: =HLOOKUP(B31,'RTN-2.2'!$A$5:$AC$164,13,0) -> 31584.585 | AW31: =HLOOKUP(B31,'RTN-2.2-A'!$A$5:$AC$164,13,0)*100 -> 1.8385039 | AZ31: =HLOOKUP(B31,'RTN-2.2'!$A$5:$AC$164,59,0) -> 260122.4 | BA31: =HLOOKUP(B31,'RTN-2.2-A'!$A$5:$AC$164,59,0)*100 -> 15.141438 | BL31: =HLOOKUP(B31,'RTN-2.2'!$A$5:$AC$164,159,0)*(-1) -> 100896.43 | BM31: =HLOOKUP(B31,'RTN-2.2-A'!$A$5:$AC$164,159,0)*100*(-1) -> 5.8730698 | BN31: =HLOOKUP(B31,'RTN-2.2'!$A$5:$AC$164,151,0) -> 39080.048 | BO31: =HLOOKUP(B31,'RTN-2.2-A'!$A$5:$AC$164,151,0)*100 -> 2.2748066
B32: 2004 | C32: 1957751.2 | G32: 5.7599646 | H32: 339087.08 | I32: =H32/C32*100 -> 17.320233 | J32: 1178695 | K32: =J32/C32*100 -> 60.206577 | L32: 257101.5 | M32: =L32/C32*100 -> 13.132491 | N32: 323924.85 | O32: =N32/C32*100 -> 16.545762 | P32: 7.5994958 | Q32: 17.75 | S32: 16.19 | T32: 2.6859 | U32: 669340 | V32: 8959.3134 | W32: =V32/U32*100 -> 1.3385295 | X32: -213.09615 | Y32: =X32/U32*100 -> -0.031836757 | Z32: 11153.288 | AA32: =Z32/U32*100 -> 1.6663114 | AB32: 2407.0713 | AC32: =AB32/U32*100 -> 0.35961862 | AD32: 52935 | AE32: =AD32/U32*100 -> 7.9085368 | AH32: 18161.38 | AI32: =AH32/U32*100 -> 2.7133266 | AJ32: =HLOOKUP(B32,'RTN-2.2'!$A$5:$AC$164,2,0) -> 418993.29 | AK32: =HLOOKUP(B32,'RTN-2.2-A'!$A$5:$AC$164,2,0)*100 -> 21.401764 | AN32: =HLOOKUP(B32,'RTN-2.2'!$A$5:$AC$164,3,0) -> 286807.67 | AO32: =HLOOKUP(B32,'RTN-2.2-A'!$A$5:$AC$164,3,0)*100 -> 14.649853 | AR32: =HLOOKUP(B32,'RTN-2.2'!$A$5:$AC$164,15,0) -> 23684.779 | AS32: =HLOOKUP(B32,'RTN-2.2-A'!$A$5:$AC$164,15,0)*100 -> 1.2097952 | AT32: =HLOOKUP(B32,'RTN-2.2'!$A$5:$AC$164,16,0) -> 17168.747 | AU32: =HLOOKUP(B32,'RTN-2.2-A'!$A$5:$AC$164,16,0)*100 -> 0.87696264 | AV32: =HLOOKUP(B32,'RTN-2.2'!$A$5:$AC$164,13,0) -> 36144.181 | AW32: =HLOOKUP(B32,'RTN-2.2-A'!$A$5:$AC$164,13,0)*100 -> 1.8462091 | AZ32: =HLOOKUP(B32,'RTN-2.2'!$A$5:$AC$164,59,0) -> 305610.66 | BA32: =HLOOKUP(B32,'RTN-2.2-A'!$A$5:$AC$164,59,0)*100 -> 15.610291 | BL32: =HLOOKUP(B32,'RTN-2.2'!$A$5:$AC$164,159,0)*(-1) -> 79418.517 | BM32: =HLOOKUP(B32,'RTN-2.2-A'!$A$5:$AC$164,159,0)*100*(-1) -> 4.0566195 | BN32: =HLOOKUP(B32,'RTN-2.2'!$A$5:$AC$164,151,0) -> 49341.425 | BO32: =HLOOKUP(B32,'RTN-2.2-A'!$A$5:$AC$164,151,0)*100 -> 2.5203113
B33: 2005 | C33: 2170584.5 | G33: 3.2021352 | H33: 370218.88 | I33: =H33/C33*100 -> 17.056183 | J33: 1313295.9 | K33: =J33/C33*100 -> 60.504252 | L33: 257061.58 | M33: =L33/C33*100 -> 11.842966 | N33: 330880.2 | O33: =N33/C33*100 -> 15.243829 | P33: 5.6892268 | Q33: 18 | S33: 16.55 | T33: 2.34129 | U33: 892033 | V33: 11679.375 | W33: =V33/U33*100 -> 1.3092985 | X33: 187.04449 | Y33: =X33/U33*100 -> 0.020968338 | Z33: 15204.315 | AA33: =Z33/U33*100 -> 1.7044565 | AB33: 3337.8952 | AC33: =AB33/U33*100 -> 0.37418965 | AD33: 53799 | AE33: =AD33/U33*100 -> 6.0310549 | AH33: 15459.982 | AI33: =AH33/U33*100 -> 1.7331177 | AJ33: =HLOOKUP(B33,'RTN-2.2'!$A$5:$AC$164,2,0) -> 487822.08 | AK33: =HLOOKUP(B33,'RTN-2.2-A'!$A$5:$AC$164,2,0)*100 -> 22.474227 | AN33: =HLOOKUP(B33,'RTN-2.2'!$A$5:$AC$164,3,0) -> 333069.63 | AO33: =HLOOKUP(B33,'RTN-2.2-A'!$A$5:$AC$164,3,0)*100 -> 15.344698 | AR33: =HLOOKUP(B33,'RTN-2.2'!$A$5:$AC$164,15,0) -> 28736.411 | AS33: =HLOOKUP(B33,'RTN-2.2-A'!$A$5:$AC$164,15,0)*100 -> 1.323902 | AT33: =HLOOKUP(B33,'RTN-2.2'!$A$5:$AC$164,16,0) -> 19967.36 | AU33: =HLOOKUP(B33,'RTN-2.2-A'!$A$5:$AC$164,16,0)*100 -> 0.91990707 | AV33: =HLOOKUP(B33,'RTN-2.2'!$A$5:$AC$164,13,0) -> 48964.977 | AW33: =HLOOKUP(B33,'RTN-2.2-A'!$A$5:$AC$164,13,0)*100 -> 2.2558429 | AZ33: =HLOOKUP(B33,'RTN-2.2'!$A$5:$AC$164,59,0) -> 354925.38 | BA33: =HLOOKUP(B33,'RTN-2.2-A'!$A$5:$AC$164,59,0)*100 -> 16.351604 | BL33: =HLOOKUP(B33,'RTN-2.2'!$A$5:$AC$164,159,0)*(-1) -> 129025.37 | BM33: =HLOOKUP(B33,'RTN-2.2-A'!$A$5:$AC$164,159,0)*100*(-1) -> 5.9442686 | BN33: =HLOOKUP(B33,'RTN-2.2'!$A$5:$AC$164,151,0) -> 52673.168 | BO33: =HLOOKUP(B33,'RTN-2.2-A'!$A$5:$AC$164,151,0)*100 -> 2.4266813
B34: 2006 | C34: 2409449.9 | G34: 3.9619887 | H34: 414673.55 | I34: =H34/C34*100 -> 17.2103 | J34: 1456215.5 | K34: =J34/C34*100 -> 60.437676 | L34: 281119.76 | M34: =L34/C34*100 -> 11.667384 | N34: 346341.95 | O34: =N34/C34*100 -> 14.374316 | P34: 3.1415161 | Q34: 13.25 | S34: 12.04 | T34: 2.14877 | U34: 1107131 | V34: 10774 | W34: =V34/U34*100 -> 0.9731459 | X34: 179.72642 | Y34: =X34/U34*100 -> 0.016233527 | Z34: 15429.69 | AA34: =Z34/U34*100 -> 1.3936644 | AB34: 4475.9639 | AC34: =AB34/U34*100 -> 0.40428494 | AD34: 85839 | AE34: =AD34/U34*100 -> 7.753283 | AH34: 19418.086 | AI34: =AH34/U34*100 -> 1.7539104 | AJ34: =HLOOKUP(B34,'RTN-2.2'!$A$5:$AC$164,2,0) -> 542810.01 | AK34: =HLOOKUP(B34,'RTN-2.2-A'!$A$5:$AC$164,2,0)*100 -> 22.528379 | AN34: =HLOOKUP(B34,'RTN-2.2'!$A$5:$AC$164,3,0) -> 359189.17 | AO34: =HLOOKUP(B34,'RTN-2.2-A'!$A$5:$AC$164,3,0)*100 -> 14.907518 | AR34: =HLOOKUP(B34,'RTN-2.2'!$A$5:$AC$164,15,0) -> 29902.243 | AS34: =HLOOKUP(B34,'RTN-2.2-A'!$A$5:$AC$164,15,0)*100 -> 1.2410402 | AT34: =HLOOKUP(B34,'RTN-2.2'!$A$5:$AC$164,16,0) -> 21293.287 | AU34: =HLOOKUP(B34,'RTN-2.2-A'!$A$5:$AC$164,16,0)*100 -> 0.88374058 | AV34: =HLOOKUP(B34,'RTN-2.2'!$A$5:$AC$164,13,0) -> 53965.864 | AW34: =HLOOKUP(B34,'RTN-2.2-A'!$A$5:$AC$164,13,0)*100 -> 2.2397587 | AZ34: =HLOOKUP(B34,'RTN-2.2'!$A$5:$AC$164,59,0) -> 403738.39 | BA34: =HLOOKUP(B34,'RTN-2.2-A'!$A$5:$AC$164,59,0)*100 -> 16.756455 | BL34: =HLOOKUP(B34,'RTN-2.2'!$A$5:$AC$164,159,0)*(-1) -> 125826.62 | BM34: =HLOOKUP(B34,'RTN-2.2-A'!$A$5:$AC$164,159,0)*100*(-1) -> 5.2222134 | BN34: =HLOOKUP(B34,'RTN-2.2'!$A$5:$AC$164,151,0) -> 48748.23 | BO34: =HLOOKUP(B34,'RTN-2.2-A'!$A$5:$AC$164,151,0)*100 -> 2.0232099
B35: 2007 | C35: 2720262.9 | G35: 6.0698706 | H35: 489532.03 | I35: =H35/C35*100 -> 17.995761 | J35: 1628756 | K35: =J35/C35*100 -> 59.874948 | L35: 325477.73 | M35: =L35/C35*100 -> 11.964936 | N35: 362547.81 | O35: =N35/C35*100 -> 13.327675 | P35: 4.4576586 | Q35: 11.25 | S35: 10.32 | T35: 1.79032 | U35: 1396797 | V35: -2753.6702 | W35: =V35/U35*100 -> -0.19714176 | X35: 249.36078 | Y35: =X35/U35*100 -> 0.017852328 | Z35: 681.90924 | AA35: =Z35/U35*100 -> 0.048819495 | AB35: 3186.2187 | AC35: =AB35/U35*100 -> 0.22810893 | AD35: 180334 | AE35: =AD35/U35*100 -> 12.910537 | AH35: 44579.492 | AI35: =AH35/U35*100 -> 3.1915513 | AJ35: =HLOOKUP(B35,'RTN-2.2'!$A$5:$AC$164,2,0) -> 618352.11 | AK35: =HLOOKUP(B35,'RTN-2.2-A'!$A$5:$AC$164,2,0)*100 -> 22.731336 | AN35: =HLOOKUP(B35,'RTN-2.2'!$A$5:$AC$164,3,0) -> 417509.44 | AO35: =HLOOKUP(B35,'RTN-2.2-A'!$A$5:$AC$164,3,0)*100 -> 15.348128 | AR35: =HLOOKUP(B35,'RTN-2.2'!$A$5:$AC$164,15,0) -> 32071.986 | AS35: =HLOOKUP(B35,'RTN-2.2-A'!$A$5:$AC$164,15,0)*100 -> 1.1790032 | AT35: =HLOOKUP(B35,'RTN-2.2'!$A$5:$AC$164,16,0) -> 21488.195 | AU35: =HLOOKUP(B35,'RTN-2.2-A'!$A$5:$AC$164,16,0)*100 -> 0.78993081 | AV35: =HLOOKUP(B35,'RTN-2.2'!$A$5:$AC$164,13,0) -> 67797.984 | AW35: =HLOOKUP(B35,'RTN-2.2-A'!$A$5:$AC$164,13,0)*100 -> 2.492332 | AZ35: =HLOOKUP(B35,'RTN-2.2'!$A$5:$AC$164,59,0) -> 458785.05 | BA35: =HLOOKUP(B35,'RTN-2.2-A'!$A$5:$AC$164,59,0)*100 -> 16.865467 | BL35: =HLOOKUP(B35,'RTN-2.2'!$A$5:$AC$164,159,0)*(-1) -> 119045.7 | BM35: =HLOOKUP(B35,'RTN-2.2-A'!$A$5:$AC$164,159,0)*100*(-1) -> 4.3762572 | BN35: =HLOOKUP(B35,'RTN-2.2'!$A$5:$AC$164,151,0) -> 57650.389 | BO35: =HLOOKUP(B35,'RTN-2.2-A'!$A$5:$AC$164,151,0)*100 -> 2.1192947
B36: 2008 | C36: 3109803.1 | G36: 5.0941954 | H36: 602845.58 | I36: =H36/C36*100 -> 19.38533 | J36: 1857510 | K36: =J36/C36*100 -> 59.730793 | L36: 426775.97 | M36: =L36/C36*100 -> 13.723569 | N36: 420880.77 | O36: =N36/C36*100 -> 13.534001 | P36: 5.9027244 | Q36: 13.75 | S36: 12.5 | T36: 2.36636 | U36: 1693147 | V36: -35601.728 | W36: =V36/U36*100 -> -2.1026956 | X36: 152.09663 | Y36: =X36/U36*100 -> 0.0089830728 | Z36: -24139.911 | AA36: =Z36/U36*100 -> -1.4257422 | AB36: 11309.72 | AC36: =AB36/U36*100 -> 0.66797036 | AD36: 193783 | AE36: =AD36/U36*100 -> 11.445137 | AH36: 50716.403 | AI36: =AH36/U36*100 -> 2.9953928 | AJ36: =HLOOKUP(B36,'RTN-2.2'!$A$5:$AC$164,2,0) -> 715615.9 | AK36: =HLOOKUP(B36,'RTN-2.2-A'!$A$5:$AC$164,2,0)*100 -> 23.011614 | AN36: =HLOOKUP(B36,'RTN-2.2'!$A$5:$AC$164,3,0) -> 466337.04 | AO36: =HLOOKUP(B36,'RTN-2.2-A'!$A$5:$AC$164,3,0)*100 -> 14.99571 | AR36: =HLOOKUP(B36,'RTN-2.2'!$A$5:$AC$164,15,0) -> 41345.879 | AS36: =HLOOKUP(B36,'RTN-2.2-A'!$A$5:$AC$164,15,0)*100 -> 1.3295337 | AT36: =HLOOKUP(B36,'RTN-2.2'!$A$5:$AC$164,16,0) -> 25585.371 | AU36: =HLOOKUP(B36,'RTN-2.2-A'!$A$5:$AC$164,16,0)*100 -> 0.82273282 | AV36: =HLOOKUP(B36,'RTN-2.2'!$A$5:$AC$164,13,0) -> 81414.289 | AW36: =HLOOKUP(B36,'RTN-2.2-A'!$A$5:$AC$164,13,0)*100 -> 2.6179886 | AZ36: =HLOOKUP(B36,'RTN-2.2'!$A$5:$AC$164,59,0) -> 516818.49 | BA36: =HLOOKUP(B36,'RTN-2.2-A'!$A$5:$AC$164,59,0)*100 -> 16.61901 | BL36: =HLOOKUP(B36,'RTN-2.2'!$A$5:$AC$164,159,0)*(-1) -> 96198.68 | BM36: =HLOOKUP(B36,'RTN-2.2-A'!$A$5:$AC$164,159,0)*100*(-1) -> 3.093401 | BN36: =HLOOKUP(B36,'RTN-2.2'!$A$5:$AC$164,151,0) -> 71438.389 | BO36: =HLOOKUP(B36,'RTN-2.2-A'!$A$5:$AC$164,151,0)*100 -> 2.2971998 | BR36: ='BCB-DBGG-anual'!B4 -> 1740887.8 | BS36: ='BCB-DBGG-anual'!C4 -> 55.980645
B37: 2009 | C37: 3333039.4 | G37: -0.125812 | H37: 636675.78 | I37: =H37/C37*100 -> 19.101958 | J37: 2065033.2 | K37: =J37/C37*100 -> 61.95646 | L37: 375120.4 | M37: =L37/C37*100 -> 11.254604 | N37: 361680.47 | O37: =N37/C37*100 -> 10.851371 | P37: 4.3116501 | Q37: 8.75 | S37: 8.16 | T37: 1.76247 | U37: 1672625 | V37: -29328.433 | W37: =V37/U37*100 -> -1.7534374 | X37: 237.2173 | Y37: =X37/U37*100 -> 0.014182336 | Z37: -23454.391 | AA37: =Z37/U37*100 -> -1.4022504 | AB37: 5636.8248 | AC37: =AB37/U37*100 -> 0.3370047 | AD37: 238520 | AE37: =AD37/U37*100 -> 14.26022 | AH37: 31480.932 | AI37: =AH37/U37*100 -> 1.8821273 | AJ37: =HLOOKUP(B37,'RTN-2.2'!$A$5:$AC$164,2,0) -> 738124.95 | AK37: =HLOOKUP(B37,'RTN-2.2-A'!$A$5:$AC$164,2,0)*100 -> 22.145701 | AN37: =HLOOKUP(B37,'RTN-2.2'!$A$5:$AC$164,3,0) -> 456139.33 | AO37: =HLOOKUP(B37,'RTN-2.2-A'!$A$5:$AC$164,3,0)*100 -> 13.685387 | AR37: =HLOOKUP(B37,'RTN-2.2'!$A$5:$AC$164,15,0) -> 42074.017 | AS37: =HLOOKUP(B37,'RTN-2.2-A'!$A$5:$AC$164,15,0)*100 -> 1.2623318 | AT37: =HLOOKUP(B37,'RTN-2.2'!$A$5:$AC$164,16,0) -> 23431.558 | AU37: =HLOOKUP(B37,'RTN-2.2-A'!$A$5:$AC$164,16,0)*100 -> 0.70300874 | AV37: =HLOOKUP(B37,'RTN-2.2'!$A$5:$AC$164,13,0) -> 81084.153 | AW37: =HLOOKUP(B37,'RTN-2.2-A'!$A$5:$AC$164,13,0)*100 -> 2.4327391 | AZ37: =HLOOKUP(B37,'RTN-2.2'!$A$5:$AC$164,59,0) -> 579009.45 | BA37: =HLOOKUP(B37,'RTN-2.2-A'!$A$5:$AC$164,59,0)*100 -> 17.371816 | BL37: =HLOOKUP(B37,'RTN-2.2'!$A$5:$AC$164,159,0)*(-1) -> 149806.4 | BM37: =HLOOKUP(B37,'RTN-2.2-A'!$A$5:$AC$164,159,0)*100*(-1) -> 4.4945884 | BN37: =HLOOKUP(B37,'RTN-2.2'!$A$5:$AC$164,151,0) -> 39436.419 | BO37: =HLOOKUP(B37,'RTN-2.2-A'!$A$5:$AC$164,151,0)*100 -> 1.1831969 | BR37: ='BCB-DBGG-anual'!B5 -> 1973423.7 | BS37: ='BCB-DBGG-anual'!C5 -> 59.207932
B38: 2010 | C38: 3885847 | G38: 7.5282258 | H38: 797946 | I38: =H38/C38*100 -> 20.534674 | J38: 2340167 | K38: =J38/C38*100 -> 60.222829 | L38: 462672 | M38: =L38/C38*100 -> 11.906593 | N38: 422220 | O38: =N38/C38*100 -> 10.865585 | P38: 5.9086887 | Q38: 10.75 | S38: 9.09 | T38: 1.68789 | U38: 2209751 | V38: -86717.778 | W38: =V38/U38*100 -> -3.9243235 | X38: 242.05349 | Y38: =X38/U38*100 -> 0.010953881 | Z38: -78059.968 | AA38: =Z38/U38*100 -> -3.5325233 | AB38: 8415.7566 | AC38: =AB38/U38*100 -> 0.38084638 | AD38: 288575 | AE38: =AD38/U38*100 -> 13.059164 | AH38: 82389.932 | AI38: =AH38/U38*100 -> 3.7284713 | AJ38: =HLOOKUP(B38,'RTN-2.2'!$A$5:$AC$164,2,0) -> 918531.37 | AK38: =HLOOKUP(B38,'RTN-2.2-A'!$A$5:$AC$164,2,0)*100 -> 23.637868 | AN38: =HLOOKUP(B38,'RTN-2.2'!$A$5:$AC$164,3,0) -> 531205.99 | AO38: =HLOOKUP(B38,'RTN-2.2-A'!$A$5:$AC$164,3,0)*100 -> 13.670276 | AR38: =HLOOKUP(B38,'RTN-2.2'!$A$5:$AC$164,15,0) -> 49144.427 | AS38: =HLOOKUP(B38,'RTN-2.2-A'!$A$5:$AC$164,15,0)*100 -> 1.2647031 | AT38: =HLOOKUP(B38,'RTN-2.2'!$A$5:$AC$164,16,0) -> 25169.452 | AU38: =HLOOKUP(B38,'RTN-2.2-A'!$A$5:$AC$164,16,0)*100 -> 0.64772114 | AV38: =HLOOKUP(B38,'RTN-2.2'!$A$5:$AC$164,13,0) -> 84874.314 | AW38: =HLOOKUP(B38,'RTN-2.2-A'!$A$5:$AC$164,13,0)*100 -> 2.1841908 | AZ38: =HLOOKUP(B38,'RTN-2.2'!$A$5:$AC$164,59,0) -> 707269.91 | BA38: =HLOOKUP(B38,'RTN-2.2-A'!$A$5:$AC$164,59,0)*100 -> 18.201178 | BL38: =HLOOKUP(B38,'RTN-2.2'!$A$5:$AC$164,159,0)*(-1) -> 124508.74 | BM38: =HLOOKUP(B38,'RTN-2.2-A'!$A$5:$AC$164,159,0)*100*(-1) -> 3.2041597 | BN38: =HLOOKUP(B38,'RTN-2.2'!$A$5:$AC$164,151,0) -> 77891.169 | BO38: =HLOOKUP(B38,'RTN-2.2-A'!$A$5:$AC$164,151,0)*100 -> 2.0044837 | BR38: ='BCB-DBGG-anual'!B6 -> 2011521.7 | BS38: ='BCB-DBGG-anual'!C6 -> 51.765334
B39: 2011 | C39: 4376382 | G39: 3.9744231 | H39: 901927 | I39: =H39/C39*100 -> 20.608964 | J39: 2637814 | K39: =J39/C39*100 -> 60.273852 | L39: 540566 | M39: =L39/C39*100 -> 12.351892 | N39: 506895 | O39: =N39/C39*100 -> 11.582513 | P39: 6.5033527 | Q39: 11 | R39: 25.783678 | S39: 10.22 | T39: 1.86119 | U39: 2614482 | V39: -83576.206 | W39: =V39/U39*100 -> -3.196664 | X39: 255.79475 | Y39: =X39/U39*100 -> 0.0097837641 | Z39: -88988.773 | AA39: =Z39/U39*100 -> -3.4036866 | AB39: -5668.3616 | AC39: =AB39/U39*100 -> -0.2168063 | AD39: 352012 | AE39: =AD39/U39*100 -> 13.463929 | AH39: 102427.23 | AI39: =AH39/U39*100 -> 3.9176873 | AJ39: =HLOOKUP(B39,'RTN-2.2'!$A$5:$AC$164,2,0) -> 988270.08 | AK39: =HLOOKUP(B39,'RTN-2.2-A'!$A$5:$AC$164,2,0)*100 -> 22.581897 | AN39: =HLOOKUP(B39,'RTN-2.2'!$A$5:$AC$164,3,0) -> 628894.93 | AO39: =HLOOKUP(B39,'RTN-2.2-A'!$A$5:$AC$164,3,0)*100 -> 14.370202 | AR39: =HLOOKUP(B39,'RTN-2.2'!$A$5:$AC$164,15,0) -> 58400.376 | AS39: =HLOOKUP(B39,'RTN-2.2-A'!$A$5:$AC$164,15,0)*100 -> 1.3344442 | AT39: =HLOOKUP(B39,'RTN-2.2'!$A$5:$AC$164,16,0) -> 35543.231 | AU39: =HLOOKUP(B39,'RTN-2.2-A'!$A$5:$AC$164,16,0)*100 -> 0.81216016 | AV39: =HLOOKUP(B39,'RTN-2.2'!$A$5:$AC$164,13,0) -> 98706.499 | AW39: =HLOOKUP(B39,'RTN-2.2-A'!$A$5:$AC$164,13,0)*100 -> 2.2554361 | AZ39: =HLOOKUP(B39,'RTN-2.2'!$A$5:$AC$164,59,0) -> 733343.38 | BA39: =HLOOKUP(B39,'RTN-2.2-A'!$A$5:$AC$164,59,0)*100 -> 16.756841 | BL39: =HLOOKUP(B39,'RTN-2.2'!$A$5:$AC$164,159,0)*(-1) -> 180553.07 | BM39: =HLOOKUP(B39,'RTN-2.2-A'!$A$5:$AC$164,159,0)*100*(-1) -> 4.1256241 | BN39: =HLOOKUP(B39,'RTN-2.2'!$A$5:$AC$164,151,0) -> 91891.031 | BO39: =HLOOKUP(B39,'RTN-2.2-A'!$A$5:$AC$164,151,0)*100 -> 2.0997032 | BR39: ='BCB-DBGG-anual'!B7 -> 2243603.7 | BS39: ='BCB-DBGG-anual'!C7 -> 51.266176
B40: 2012 | C40: 4814760 | G40: 1.921176 | H40: 997460 | I40: =H40/C40*100 -> 20.716713 | J40: 2956834 | K40: =J40/C40*100 -> 61.411867 | L40: 637317 | M40: =L40/C40*100 -> 13.236735 | N40: 571875 | O40: =N40/C40*100 -> 11.877539 | P40: 5.8385947 | Q40: 7.25 | R40: 20.412703 | S40: 6.64 | T40: 2.06738 | U40: 2463549 | V40: -92678.171 | W40: =V40/U40*100 -> -3.761978 | X40: 207.9143 | Y40: =X40/U40*100 -> 0.0084396251 | Z40: -93929.695 | AA40: =Z40/U40*100 -> -3.8127797 | AB40: -1459.4381 | AC40: =AB40/U40*100 -> -0.059241287 | AD40: 373147 | AE40: =AD40/U40*100 -> 15.146725 | AH40: 92568.388 | AI40: =AH40/U40*100 -> 3.7575217 | AJ40: =HLOOKUP(B40,'RTN-2.2'!$A$5:$AC$164,2,0) -> 1072289.4 | AK40: =HLOOKUP(B40,'RTN-2.2-A'!$A$5:$AC$164,2,0)*100 -> 22.27088 | AN40: =HLOOKUP(B40,'RTN-2.2'!$A$5:$AC$164,3,0) -> 647535.06 | AO40: =HLOOKUP(B40,'RTN-2.2-A'!$A$5:$AC$164,3,0)*100 -> 13.448958 | AR40: =HLOOKUP(B40,'RTN-2.2'!$A$5:$AC$164,15,0) -> 63933.98 | AS40: =HLOOKUP(B40,'RTN-2.2-A'!$A$5:$AC$164,15,0)*100 -> 1.3278747 | AT40: =HLOOKUP(B40,'RTN-2.2'!$A$5:$AC$164,16,0) -> 33853.764 | AU40: =HLOOKUP(B40,'RTN-2.2-A'!$A$5:$AC$164,16,0)*100 -> 0.70312464 | AV40: =HLOOKUP(B40,'RTN-2.2'!$A$5:$AC$164,13,0) -> 101104.32 | AW40: =HLOOKUP(B40,'RTN-2.2-A'!$A$5:$AC$164,13,0)*100 -> 2.0998829 | AZ40: =HLOOKUP(B40,'RTN-2.2'!$A$5:$AC$164,59,0) -> 815907.02 | BA40: =HLOOKUP(B40,'RTN-2.2-A'!$A$5:$AC$164,59,0)*100 -> 16.945954 | BL40: =HLOOKUP(B40,'RTN-2.2'!$A$5:$AC$164,159,0)*(-1) -> 147267.63 | BM40: =HLOOKUP(B40,'RTN-2.2-A'!$A$5:$AC$164,159,0)*100*(-1) -> 3.0586703 | BN40: =HLOOKUP(B40,'RTN-2.2'!$A$5:$AC$164,151,0) -> 84987.966 | BO40: =HLOOKUP(B40,'RTN-2.2-A'!$A$5:$AC$164,151,0)*100 -> 1.7651548 | BR40: ='BCB-DBGG-anual'!B8 -> 2583946.4 | BS40: ='BCB-DBGG-anual'!C8 -> 53.667189
B41: 2013 | C41: 5331619 | G41: 3.0048227 | H41: 1114944 | I41: =H41/C41*100 -> 20.911922 | J41: 3290422 | K41: =J41/C41*100 -> 61.71525 | L41: 748758 | M41: =L41/C41*100 -> 14.043727 | N41: 626051 | O41: =N41/C41*100 -> 11.742231 | P41: 5.9106833 | Q41: 10 | R41: 21.843191 | S41: 9.19 | T41: 2.34997 | U41: 2468456 | V41: -88384.03 | W41: =V41/U41*100 -> -3.580539 | X41: 322.25374 | Y41: =X41/U41*100 -> 0.013054871 | Z41: -89601.939 | AA41: =Z41/U41*100 -> -3.6298779 | AB41: -1540.1626 | AC41: =AB41/U41*100 -> -0.062393764 | AD41: 358808 | AE41: =AD41/U41*100 -> 14.535726 | AH41: 75211.029 | AI41: =AH41/U41*100 -> 3.0468855 | AJ41: =HLOOKUP(B41,'RTN-2.2'!$A$5:$AC$164,2,0) -> 1178983.2 | AK41: =HLOOKUP(B41,'RTN-2.2-A'!$A$5:$AC$164,2,0)*100 -> 22.113044 | AN41: =HLOOKUP(B41,'RTN-2.2'!$A$5:$AC$164,3,0) -> 720193.37 | AO41: =HLOOKUP(B41,'RTN-2.2-A'!$A$5:$AC$164,3,0)*100 -> 13.507968 | AR41: =HLOOKUP(B41,'RTN-2.2'!$A$5:$AC$164,15,0) -> 66881.97 | AS41: =HLOOKUP(B41,'RTN-2.2-A'!$A$5:$AC$164,15,0)*100 -> 1.2544402 | AT41: =HLOOKUP(B41,'RTN-2.2'!$A$5:$AC$164,16,0) -> 37035.331 | AU41: =HLOOKUP(B41,'RTN-2.2-A'!$A$5:$AC$164,16,0)*100 -> 0.69463573 | AV41: =HLOOKUP(B41,'RTN-2.2'!$A$5:$AC$164,13,0) -> 114143.61 | AW41: =HLOOKUP(B41,'RTN-2.2-A'!$A$5:$AC$164,13,0)*100 -> 2.1408808 | AZ41: =HLOOKUP(B41,'RTN-2.2'!$A$5:$AC$164,59,0) -> 924929.13 | BA41: =HLOOKUP(B41,'RTN-2.2-A'!$A$5:$AC$164,59,0)*100 -> 17.347998 | BL41: =HLOOKUP(B41,'RTN-2.2'!$A$5:$AC$164,159,0)*(-1) -> 185845.65 | BM41: =HLOOKUP(B41,'RTN-2.2-A'!$A$5:$AC$164,159,0)*100*(-1) -> 3.4857264 | BN41: =HLOOKUP(B41,'RTN-2.2'!$A$5:$AC$164,151,0) -> 72159.145 | BO41: =HLOOKUP(B41,'RTN-2.2-A'!$A$5:$AC$164,151,0)*100 -> 1.353419 | BR41: ='BCB-DBGG-anual'!B9 -> 2747996.7 | BS41: ='BCB-DBGG-anual'!C9 -> 51.541506
